<?xml version="1.0"?>
<robot xmlns:xacro="http://www.ros.org/wiki/xacro" name="u_shaped_collector_v2">

  <!-- ======================================================================= -->
  <!--                           PROPERTIES (CONSTANTS)                        -->
  <!-- ======================================================================= -->
  
  <!-- Base Dimensions -->
  <xacro:property name="base_len" value="0.1"/>
  <xacro:property name="base_width" value="0.42"/>
  <xacro:property name="base_height" value="0.2"/>
  <xacro:property name="base_mass" value="10.0"/>

  <!-- U-Arm Dimensions -->
  <xacro:property name="arm_len" value="0.35"/>
  <xacro:property name="arm_thick" value="0.05"/>
  <xacro:property name="arm_height" value="0.2"/>
  <xacro:property name="arm_y_offset" value="0.185"/> <!-- Distance from center to arm center -->
  <xacro:property name="arm_x_offset" value="0.225"/>

  <!-- Wheel Dimensions -->
  <xacro:property name="wheel_radius" value="0.06"/>
  <xacro:property name="wheel_width" value="0.04"/>
  <xacro:property name="wheel_mass" value="0.5"/>
  <xacro:property name="wheel_x_offset" value="0.3"/>
  <xacro:property name="wheel_y_offset" value="0.235"/>
  <xacro:property name="wheel_z_offset" value="-0.08"/>

  <!-- Caster Dimensions -->
  <xacro:property name="caster_radius" value="0.04"/>
  <xacro:property name="caster_mass" value="0.2"/>
  <xacro:property name="caster_x_offset" value="-0.01"/>
  <xacro:property name="caster_z_offset" value="-0.10"/>

  <!-- Gate Dimensions -->
  <xacro:property name="gate_thick" value="0.02"/>
  <xacro:property name="gate_len" value="0.18"/>
  <xacro:property name="gate_height" value="0.18"/>
  <xacro:property name="gate_mass" value="0.1"/>
  <xacro:property name="gate_x_mount" value="0.4"/>
  <xacro:property name="gate_y_mount" value="0.25"/> <!-- Adjusted offset per previous request -->
  <xacro:property name="gate_travel" value="0.25"/>

  <!-- Colors -->
  <material name="blue"><color rgba="0 0 0.8 1"/></material>
  <material name="black"><color rgba="0 0 0 1"/></material>
  <material name="red"><color rgba="0.8 0 0 1"/></material>
  <material name="silver"><color rgba="0.7 0.7 0.7 1"/></material>


  <!-- ======================================================================= -->
  <!--                           INERTIA MACROS                                -->
  <!-- ======================================================================= -->

  <xacro:macro name="box_inertia" params="m l w h">
    <inertial>
      <mass value="${m}"/>
      <inertia ixx="${(m/12) * (h*h + l*l)}" ixy="0.0" ixz="0.0" 
               iyy="${(m/12) * (w*w + l*l)}" iyz="0.0" 
               izz="${(m/12) * (w*w + h*h)}"/>
    </inertial>
  </xacro:macro>

  <xacro:macro name="cylinder_inertia" params="m r h">
    <inertial>
      <mass value="${m}"/>
      <inertia ixx="${(m/12) * (3*r*r + h*h)}" ixy="0" ixz="0" 
               iyy="${(m/12) * (3*r*r + h*h)}" iyz="0" 
               izz="${(m*r*r)/2}"/>
    </inertial>
  </xacro:macro>

  <xacro:macro name="sphere_inertia" params="m r">
    <inertial>
      <mass value="${m}"/>
      <inertia ixx="${(2/5) * m * r * r}" ixy="0" ixz="0" 
               iyy="${(2/5) * m * r * r}" iyz="0" 
               izz="${(2/5) * m * r * r}"/>
    </inertial>
  </xacro:macro>


  <!-- ======================================================================= -->
  <!--                           COMPONENT MACROS                              -->
  <!-- ======================================================================= -->

  <!-- Wheel Macro -->
  <xacro:macro name="wheel" params="prefix reflect">
    <link name="${prefix}_wheel">
      <visual>
        <geometry><cylinder length="${wheel_width}" radius="${wheel_radius}"/></geometry>
        <material name="black"/>
      </visual>
      <collision>
        <geometry><cylinder length="${wheel_width}" radius="${wheel_radius}"/></geometry>
      </collision>
      <xacro:cylinder_inertia m="${wheel_mass}" r="${wheel_radius}" h="${wheel_width}"/>
    </link>

    <joint name="${prefix}_wheel_joint" type="continuous">
      <parent link="base_link"/>
      <child link="${prefix}_wheel"/>
      <!-- reflect is 1 for left, -1 for right -->
      <origin xyz="${wheel_x_offset} ${reflect * wheel_y_offset} ${wheel_z_offset}" rpy="-1.5708 0 0"/>
      <axis xyz="0 0 1"/>
    </joint>
  </xacro:macro>

  <!-- Sliding Gate Macro -->
  <xacro:macro name="sliding_gate" params="prefix y_pos lower_lim upper_lim">
    <link name="${prefix}_gate">
      <visual>
        <geometry><box size="${gate_thick} ${gate_len} ${gate_height}"/></geometry>
        <material name="red"/>
      </visual>
      <collision>
        <geometry><box size="${gate_thick} ${gate_len} ${gate_height}"/></geometry>
      </collision>
      <xacro:box_inertia m="${gate_mass}" l="${gate_thick}" w="${gate_len}" h="${gate_height}"/>
    </link>

    <joint name="${prefix}_gate_joint" type="prismatic">
      <parent link="base_link"/>
      <child link="${prefix}_gate"/>
      <origin xyz="${gate_x_mount} ${y_pos} 0" rpy="0 0 0"/>
      <axis xyz="0 1 0"/>
      <limit lower="${lower_lim}" upper="${upper_lim}" effort="10" velocity="0.5"/>
    </joint>

    <!-- Individual controller plugin for this gate -->
    <gazebo>
      <plugin filename="gz-sim-joint-position-controller-system" name="gz::sim::systems::JointPositionController">
        <joint_name>${prefix}_gate_joint</joint_name>
        <p_gain>10</p_gain>
        <i_gain>0.1</i_gain>
        <d_gain>0.1</d_gain>
        <topic>gate/${prefix}/cmd_pos</topic>
      </plugin>
    </gazebo>
  </xacro:macro>


  <!-- ======================================================================= -->
  <!--                           MAIN ROBOT STRUCTURE                          -->
  <!-- ======================================================================= -->

  <!-- Base Footprint (World Ground Projection) -->
  <link name="base_footprint"/>

  <joint name="base_joint" type="fixed">
    <parent link="base_footprint"/>
    <child link="base_link"/>
    <origin xyz="0 0 0.14" rpy="0 0 0"/>
  </joint>

  <!-- Base Link (Complex Shape: Center + 2 Arms) -->
  <link name="base_link">
    <!-- 1. Center Body -->
    <visual>
      <origin xyz="0 0 0"/>
      <geometry><box size="${base_len} ${base_width} ${base_height}"/></geometry>
      <material name="blue"/>
    </visual>
    <collision>
      <origin xyz="0 0 0"/>
      <geometry><box size="${base_len} ${base_width} ${base_height}"/></geometry>
    </collision>

    <!-- 2. Left Arm -->
    <visual>
      <origin xyz="${arm_x_offset} ${arm_y_offset} 0"/>
      <geometry><box size="${arm_len} ${arm_thick} ${arm_height}"/></geometry>
      <material name="blue"/>
    </visual>
    <collision>
      <origin xyz="${arm_x_offset} ${arm_y_offset} 0"/>
      <geometry><box size="${arm_len} ${arm_thick} ${arm_height}"/></geometry>
    </collision>

    <!-- 3. Right Arm -->
    <visual>
      <origin xyz="${arm_x_offset} -${arm_y_offset} 0"/>
      <geometry><box size="${arm_len} ${arm_thick} ${arm_height}"/></geometry>
      <material name="blue"/>
    </visual>
    <collision>
      <origin xyz="${arm_x_offset} -${arm_y_offset} 0"/>
      <geometry><box size="${arm_len} ${arm_thick} ${arm_height}"/></geometry>
    </collision>

    <!-- Combined Inertia (Simplified as one big box for stability) -->
    <xacro:box_inertia m="${base_mass}" l="0.4" w="0.42" h="0.2"/>
  </link>

  <!-- Instantiate Wheels -->
  <xacro:wheel prefix="left" reflect="1"/>
  <xacro:wheel prefix="right" reflect="-1"/>

  <!-- Instantiate Caster Wheel -->
  <link name="caster_wheel">
    <visual>
      <geometry><sphere radius="${caster_radius}"/></geometry>
      <material name="silver"/>
    </visual>
    <collision>
      <geometry><sphere radius="${caster_radius}"/></geometry>
    </collision>
    <xacro:sphere_inertia m="${caster_mass}" r="${caster_radius}"/>
  </link>
  <joint name="caster_joint" type="fixed">
    <parent link="base_link"/>
    <child link="caster_wheel"/>
    <origin xyz="${caster_x_offset} 0 ${caster_z_offset}"/> 
  </joint>
  <gazebo reference="caster_wheel">
    <mu1>0.0</mu1><mu2>0.0</mu2>
    <material>Gazebo/Silver</material>
  </gazebo>

  <!-- Instantiate Sliding Gates -->
  <xacro:sliding_gate prefix="left" y_pos="${gate_y_mount}" lower_lim="-${gate_travel}" upper_lim="0"/>
  <xacro:sliding_gate prefix="right" y_pos="-${gate_y_mount}" lower_lim="0" upper_lim="${gate_travel}"/>


  <!-- ======================================================================= -->
  <!--                           SENSORS                                       -->
  <!-- ======================================================================= -->

  <!-- LiDAR -->
  <link name="lidar_link">
    <visual>
      <geometry><cylinder length="0.04" radius="0.04"/></geometry>
      <material name="black"/>
    </visual>
    <collision>
      <geometry><cylinder length="0.04" radius="0.04"/></geometry>
    </collision>
    <xacro:cylinder_inertia m="0.1" r="0.04" h="0.04"/>
  </link>
  <joint name="lidar_joint" type="fixed">
    <parent link="base_link"/>
    <child link="lidar_link"/>
    <origin xyz="-0.01 0 0.12" rpy="0 0 0"/>
  </joint>
  <gazebo reference="lidar_link">
    <sensor name="lidar" type="gpu_lidar">
      <always_on>true</always_on>
      <visualize>true</visualize>
      <update_rate>10</update_rate>
      <topic>scan</topic>
      <gz_frame_id>lidar_link</gz_frame_id>
      <ray>
        <scan>
          <horizontal>
            <samples>360</samples>
            <resolution>1</resolution>
            <min_angle>-3.14</min_angle>
            <max_angle>3.14</max_angle>
          </horizontal>
        </scan>
        <range>
          <min>0.10</min>
          <max>10.0</max>
          <resolution>0.01</resolution>
        </range>
      </ray>
    </sensor>
  </gazebo>

  <!-- Camera -->
  <link name="camera_link">
    <visual>
      <geometry><box size="0.02 0.1 0.05"/></geometry>
      <material name="red"/>
    </visual>
    <!-- Camera is lightweight, negligible inertia/collision for simulation simplicity usually -->
  </link>
  <joint name="camera_joint" type="fixed">
    <parent link="base_link"/>
    <child link="camera_link"/>
    <origin xyz="0.06 0 0.0" rpy="0 0 0"/>
  </joint>
  <gazebo reference="camera_link">
    <sensor name="camera" type="camera">
      <always_on>true</always_on>
      <visualize>true</visualize>
      <update_rate>30</update_rate>
      <topic>camera/image_raw</topic>
      <gz_frame_id>camera_link</gz_frame_id>
      <camera name="intel_realsense_r200">
        <horizontal_fov>1.02974</horizontal_fov>
        <image>
          <width>1920</width>
          <height>1080</height>
          <format>R8G8B8</format>
        </image>
        <clip>
          <near>0.02</near>
          <far>300</far>
        </clip>
        <noise>
          <type>gaussian</type>
          <mean>0.0</mean>
          <stddev>0.007</stddev>
        </noise>
      </camera>
    </sensor>
  </gazebo>

  <!-- IMU -->
  <link name="imu_link">
    <inertial>
      <mass value="0.01"/>
      <inertia ixx="0.0001" ixy="0" ixz="0" iyy="0.0001" iyz="0" izz="0.0001"/>
    </inertial>
  </link>
  <joint name="imu_joint" type="fixed">
    <parent link="base_link"/>
    <child link="imu_link"/>
    <origin xyz="0 0 0" rpy="0 0 0"/>
  </joint>
  <gazebo reference="imu_link">
    <sensor name="imu" type="imu">
      <always_on>true</always_on>
      <update_rate>100</update_rate>
      <topic>imu</topic>
      <gz_frame_id>imu_link</gz_frame_id>
      <imu>
        <angular_velocity>
          <x><noise type="gaussian"><mean>0.0</mean><stddev>2e-4</stddev></noise></x>
          <y><noise type="gaussian"><mean>0.0</mean><stddev>2e-4</stddev></noise></y>
          <z><noise type="gaussian"><mean>0.0</mean><stddev>2e-4</stddev></noise></z>
        </angular_velocity>
        <linear_acceleration>
          <x><noise type="gaussian"><mean>0.0</mean><stddev>1.7e-2</stddev></noise></x>
          <y><noise type="gaussian"><mean>0.0</mean><stddev>1.7e-2</stddev></noise></y>
          <z><noise type="gaussian"><mean>0.0</mean><stddev>1.7e-2</stddev></noise></z>
        </linear_acceleration>
      </imu>
    </sensor>
  </gazebo>


  <!-- ======================================================================= -->
  <!--                           GAZEBO PLUGINS                                -->
  <!-- ======================================================================= -->

  <gazebo>
    <!-- Joint State Publisher (Publishes /joint_states) -->
    <plugin filename="gz-sim-joint-state-publisher-system" name="gz::sim::systems::JointStatePublisher">
      <topic>joint_states</topic>
    </plugin>

    <!-- Differential Drive Controller -->
    <plugin filename="gz-sim-diff-drive-system" name="gz::sim::systems::DiffDrive">
      <left_joint>left_wheel_joint</left_joint>
      <right_joint>right_wheel_joint</right_joint>
      <wheel_separation>0.47</wheel_separation>
      <wheel_radius>${wheel_radius}</wheel_radius>
      <odom_publish_frequency>20</odom_publish_frequency>
      <topic>cmd_vel</topic>
      <odom_topic>odom</odom_topic>
      <tf_topic>tf</tf_topic>
      <frame_id>odom</frame_id>
      <child_frame_id>base_footprint</child_frame_id>
    </plugin>

    <!-- Odometry Publisher (Ground Truth) -->
    <plugin filename="gz-sim-odometry-publisher-system" name="gz::sim::systems::OdometryPublisher">
      <odom_frame>odom</odom_frame>
      <robot_base_frame>base_footprint</robot_base_frame>
      <odom_publish_frequency>50</odom_publish_frequency>
      <odom_topic>odom</odom_topic>
      <tf_topic>tf</tf_topic>
      <dimensions>3</dimensions>
    </plugin>

    <!-- IMU System -->
    <plugin filename="gz-sim-imu-system" name="gz::sim::systems::Imu">
    </plugin>
  </gazebo>

</robot>